Workbook

Sheet LifeNumber
B2: SU YHI LIFE NUMBER
B3: Personal Fortune Enlighment
B4: Today Date | C4: : | D4: 46215 | K4: CALCULATION SHEET
B5: Name | C5: : | D5: 尤建茗 | F5: SHIO | K5: Date & Month | Q5: =HLOOKUP((M8+U8+Q12),L123:DG124,2,FALSE) -> 4 | S5: Year Of Birth | AA5: THN BERJALAN
B6: D.O.B | C6: : | D6: 30277 | F6: {=IFERROR(INDEX(SHIO!$D$5:$D$155,MATCH(1,(INT($D$6)>=INT(SHIO!$B$5:$B$155))*(INT($D$6)<=INT(SHIO!$C$5:$C$155)),0)),"Tidak ditemukan")} -> Tidak ditemukan | I6: {=IFERROR(INDEX(SHIO!$E$5:$E$155,MATCH(1,(INT($D$6)>=INT(SHIO!$B$5:$B$155))*(INT($D$6)<=INT(SHIO!$C$5:$C$155)),0)),"Tidak ditemukan")} -> Tidak ditemukan | M6: =MID(TEXT($D$6,"dd/mm/yyyy"),1,2) -> 22 | O6: =MID(TEXT($D$6,"dd/mm/yyyy"),4,2) -> 11 | S6: =MID(TEXT($D$6,"dd/mm/yyyy"),7,2) -> 19 | U6: =MID(TEXT($D$6,"dd/mm/yyyy"),9,2) -> 82 | AA6: =MID(AD6,1,2) -> 20 | AC6: =MID(AD6,3,2) -> 26 | AD6: =IF(MONTH($D$4)=10,YEAR($D$4)+1,YEAR($D$4)) -> 2026
B7: =+F7&G7&H7 -> 426 | C7: 1 | D7: DNA Ayah | E7: : | F7: =+M8 -> 4 | G7: =+O8 -> 2 | H7: =+N9 -> 6
B8: =+F8&G8&H8 -> 112 | C8: 2 | D8: DNA Ibu | E8: : | F8: =+S8 -> 1 | G8: =+U8 -> 1 | H8: =+T9 -> 2 | L8: v | M8: =HLOOKUP(VALUE(M6),$K$123:$DG$124,2,FALSE) -> 4 | O8: =HLOOKUP(VALUE(O6),$K$123:$DG$124,2,FALSE) -> 2 | S8: =HLOOKUP(VALUE(S6),$K$123:$DG$124,2,FALSE) -> 1 | U8: =HLOOKUP(VALUE(U6),$K$123:$DG$124,2,FALSE) -> 1 | V8: v | AA8: =HLOOKUP(VALUE(AA6),$K$123:$DG$124,2,FALSE) -> 2 | AC8: =HLOOKUP(VALUE(AC6),$K$123:$DG$124,2,FALSE) -> 8
B9: =+F9&G9&H9 -> 628 | C9: 3 | D9: Karakter Utama | E9: : | F9: =+N9 -> 6 | G9: =+T9 -> 2 | H9: =+Q12 -> 8 | N9: =HLOOKUP((M8+O8),$K$123:$DG$124,2,FALSE) -> 6 | T9: =HLOOKUP((S8+U8),$K$123:$DG$124,2,FALSE) -> 2 | AB9: =HLOOKUP((AA8+AC8),$K$123:$DG$124,2,FALSE) -> 1
B10: =+F10&G10&H10 -> 685 | C10: 4 | D10: P. Hidup(1) | E10: : | F10: =+N9 -> 6 | G10: =+Q12 -> 8 | H10: =+U15 -> 5
B11: =+F11&G11&H11 -> 281 | C11: 5 | D11: P. Hidup(2) | E11: : | F11: =+T9 -> 2 | G11: =+Q12 -> 8 | H11: =+M15 -> 1 | Q11: =HLOOKUP((N9+AB9),$K$123:$DG$124,2,FALSE) -> 7
B12: =+F12&G12&H12 -> 156 | C12: 6 | D12: Anak | E12: : | F12: =+M15 -> 1 | G12: =+U15 -> 5 | H12: =+Q17 -> 6 | Q12: =HLOOKUP((N9+T9),$K$123:$DG$124,2,FALSE) -> 8
B13: =+F13&G13&H13 -> 461 | C13: 7 | D13: P. Karir(1) | E13: : | F13: =M8 -> 4 | G13: =+N9 -> 6 | H13: =+O17 -> 1 | Q13: v
B14: =+F14&G14&H14 -> 268 | C14: 8 | D14: P. Karir(2) | E14: : | F14: =+O8 -> 2 | G14: =+N9 -> 6 | H14: =+N17 -> 8
B15: =+F15&G15&H15 -> 189 | C15: 9 | D15: Teman | E15: : | F15: =+O17 -> 1 | G15: =+N17 -> 8 | H15: =+M17 -> 9 | M15: =HLOOKUP((T9+Q12),$K$123:$DG$124,2,FALSE) -> 1 | U15: =HLOOKUP((N9+Q12),$K$123:$DG$124,2,FALSE) -> 5
B16: =+F16&G16&H16 -> 123 | C16: 10 | D16: P. Pernikahan(1) | E16: : | F16: =+S8 -> 1 | G16: =+T9 -> 2 | H16: =+S17 -> 3
B17: =+F17&G17&H17 -> 123 | C17: 11 | D17: P. Pernikahan(2) | E17: : | F17: =+U8 -> 1 | G17: =+T9 -> 2 | H17: =+T17 -> 3 | M17: =HLOOKUP((N17+O17),$K$123:$DG$124,2,FALSE) -> 9 | N17: =HLOOKUP((O8+N9),$K$123:$DG$124,2,FALSE) -> 8 | O17: =HLOOKUP((M8+N9),$K$123:$DG$124,2,FALSE) -> 1 | Q17: =HLOOKUP((M15+U15),$K$123:$DG$124,2,FALSE) -> 6 | S17: =HLOOKUP((S8+T9),$K$123:$DG$124,2,FALSE) -> 3 | T17: =HLOOKUP((U8+T9),$K$123:$DG$124,2,FALSE) -> 3 | U17: =HLOOKUP((S17+T17),$K$123:$DG$124,2,FALSE) -> 6 | AA17: =HLOOKUP((AA8+AB9),$K$123:$DG$124,2,FALSE) -> 3 | AB17: =HLOOKUP((AC8+AB9),$K$123:$DG$124,2,FALSE) -> 9 | AC17: =HLOOKUP((AA17+AB17),$K$123:$DG$124,2,FALSE) -> 3
B18: =+F18&G18&H18 -> 336 | C18: 12 | D18: Masa Depan | E18: : | F18: =+S17 -> 3 | G18: =+T17 -> 3 | H18: =+U17 -> 6
B19: =+F19&G19&H19 -> 347 | C19: 13 | D19: Alam Bawah Sadar | E19: : | F19: =HLOOKUP((F9+F9),$K$123:$DG$124,2,FALSE) -> 3 | G19: =HLOOKUP((G9+G9),$K$123:$DG$124,2,FALSE) -> 4 | H19: =HLOOKUP((H9+H9),$K$123:$DG$124,2,FALSE) -> 7 | K19: Main Character | N19: =+$Q$12 -> 8 | O19: =VLOOKUP(N19,ELEMEN!$A$3:$B$11,2,FALSE) -> API | Q19: (ELEMEN UTAMA)
K20: Basic Character | N20: =+B9 -> 628
D21: MISSING NUMBER | K21: F | L21: =VLOOKUP($N$19,ELEMEN!$A$3:$I$11,3,FALSE) -> TERLAHIR SEBAGAI SEORANG YG MEMPUNYAI SIFAT TANGGUNG JAWAB
D22: =TRIM(IF(COUNTIF($K$117:$Q$117, 1)=0,"1 "," ")&IF(COUNTIF($K$117:$Q$117, 2)=0,"2 "," ")&IF(COUNTIF($K$117:$Q$117, 3)=0,"3 "," ")&IF(COUNTIF($K$117:$Q$117, 4)=0,"4 "," ")&IF(COUNTIF($K$117:$Q$117, 5)=0,"5 "," ")&IF(COUNTIF($K$117:$Q$117, 6)=0,"6 "," ")&IF(COUNTIF($K$117:$Q$117, 7)=0,"7 "," ")&IF(COUNTIF($K$117:$Q$117, 8)=0,"8 "," ")&IF(COUNTIF($K$117:$Q$117, 9)=0,"9 "," ")) -> 3 5 7 9 | K22: F | L22: =VLOOKUP($N$19,ELEMEN!$A$3:$I$11,4,FALSE) -> MENGUTAMAKAN ORANG LAIN (PERHATIAN)
K23: F | L23: =VLOOKUP($N$19,ELEMEN!$A$3:$I$11,5,FALSE) -> MEMPUNYAI ETOS KERJA
C24: CYCLE OF LUCKY YEAR | K24: F | L24: =VLOOKUP($N$19,ELEMEN!$A$3:$I$11,6,FALSE) -> JUJUR & BERINTEGRITAS & DERMAWAN
C25: =+$Q$11& " #" -> 7 # | E25: =VLOOKUP(AB9,ELEMEN!$A$3:$B$11,2,FALSE) -> LOGAM | K25: s | L25: =VLOOKUP($N$19,ELEMEN!$A$3:$I$11,7,FALSE) -> KURANG BERPIKIR KE DIRI SENDIRI
C26: TAHUN UNTUK | K26: s | L26: =VLOOKUP($N$19,ELEMEN!$A$3:$I$11,8,FALSE) -> STRESS&KURANG WAKTU SENDIRI
C27: F | D27: =VLOOKUP($Q$11,ELEMEN!$A$3:$N$11,13,FALSE) -> MEMBANGUN RELASI | K27: s | L27: =VLOOKUP($N$19,ELEMEN!$A$3:$I$11,9,FALSE) -> PERFEKSIONIS(SUSAH MENDELEGASI)
C28: F | D28: =VLOOKUP($Q$11,ELEMEN!$A$3:$N$11,14,FALSE) -> PENUH KEJUTAN
C29: F | D29: =VLOOKUP($Q$11,ELEMEN!$A$3:$O$12,15,FALSE) -> KEBERUNTUNGAN TINGGI | K29: Impian Hidup (Bawaan Lahir) | P29: =+Q5 -> 4 | Q29: =VLOOKUP(P29,ELEMEN!$A$22:$D$30,3,FALSE) -> MENJADI PLANNER (KONSELOR, KONSULTAN)
K30: Dalam Segitiga butuh Angka | P30: =VLOOKUP(P29,ELEMEN!$A$22:$E$30,4,FALSE) -> 2 (Komunikasi), 4 (Rencana), 9 (Hasil)
P31: =VLOOKUP(P29,ELEMEN!$A$22:$E$30,5,FALSE)
E33: 5 BLESSING NUMBER | K33: =TRIM(IF(COUNTIF($K$117:$Q$117,4)>=1,"4","")) -> 4 | L33: =IF(K33="","",VLOOKUP(INT(K33),ELEMEN!A14:C18,3,FALSE)) -> Mendapatkan Berkat KEBAHAGIAN ( Lahan / Tanah / Perumahan / Aset )
K34: =TRIM(IF(COUNTIF($K$117:$Q$117,5)>=1,"5","")) | L34: =IF(K34="","",VLOOKUP(INT(K34),ELEMEN!A15:C19,3,FALSE))
K35: =TRIM(IF(COUNTIF($K$117:$Q$117,6)>=1,"6","")) -> 6 | L35: =IF(K35="","",VLOOKUP(INT(K35),ELEMEN!A16:C20,3,FALSE)) -> Mendapatkan Berkat KEBERUNTUNGAN/KEBIJAKSANAAN (Makan / Kekayaan)
K36: =TRIM(IF(COUNTIF($K$117:$Q$117,7)>=1,"7","")) | L36: =IF(K36="","",VLOOKUP(INT(K36),ELEMEN!A17:C21,3,FALSE))
K37: =TRIM(IF(COUNTIF($K$117:$Q$117,9)>=1,"9","")) | L37: =IF(K37="","",VLOOKUP(INT(K37),ELEMEN!A18:C22,3,FALSE))
E39: HUBUNGAN DENGAN SHIO | K39: 3 SERANGKAI | P39: =VLOOKUP($F$6,SHIO!$J$5:$N$16,2,FALSE) -> #N/A
K40: 3 CABANG DUNIAWI | P40: =VLOOKUP($F$6,SHIO!$J$5:$N$16,3,FALSE) -> #N/A
K41: =IF(OR(ISNUMBER(SEARCH("Babi",$F$6)),ISNUMBER(SEARCH("Macan",$F$6)),ISNUMBER(SEARCH("Ular",$F$6)),ISNUMBER(SEARCH("Monyet",$F$6))),"BERTENTANGAN/MELUKAI",IF(OR(ISNUMBER(SEARCH("Kerbau",$F$6)),ISNUMBER(SEARCH("Naga",$F6)),ISNUMBER(SEARCH("Kambing",$F$6)),ISNUMBER(SEARCH("Anjing",$F$6))),"TERJEBAK FISIK & MENTAL","4 JODOH BESAR")) -> 4 JODOH BESAR | P41: =VLOOKUP($F$6,SHIO!$J$5:$N$16,4,FALSE) -> #N/A
K43: Color According Our Element | P43: =VLOOKUP($N$19,ELEMEN!A$3:L$11,10,FALSE) -> MERAH, MERAH JAMBU, UNGU, ORANGE
K44: Color Reinforce Our Element | P44: =VLOOKUP($N$19,ELEMEN!A$3:L$11,11,FALSE) -> HIJAU, CYAN
...

Sheet SHIO
A1: TABEL SHIO BERDASARKAN PENANGGALAN IMLEK (TAHUN BARU IMLEK)
A2: Shio ditentukan berdasarkan Tahun Baru Imlek · Periode = Tahun Baru Imlek s/d sehari sebelum Tahun Baru Imlek berikutnya
A3: No | B3: Mulai | C3: Sampai | D3: Shio (ID) | E3: Elemen | F3: Yin/Yang | G3: Karakteristik
B4: (Tahun Baru Imlek) | I4: No | K4: Tiga Serangkai Duniawi | L4: Tiga Cabang Duniawi | M4: Menyakiti, Bertentangan, Jodoh | N4: Enam Harmoni
A5: 1 | B5: 31 | C5: 18/02/1901 | D5: 鼠 Tikus 🐭 | E5: Logam | F5: Yang | G5: Cerdas, adaptif, oportunis | I5: 1 | J5: 鼠 Tikus 🐭 | K5: 龍 Naga 🐲, 猴 Monyet 🐒 | L5: 牛 Kerbau 🐃, 豬 Babi 🐷 | M5: 馬 Kuda 🐴 | N5: 牛 Kerbau 🐃
A6: 2 | B6: 19/02/1901 | C6: 07/02/1902 | D6: 牛 Kerbau 🐃 | E6: Logam | F6: Yin | G6: Tekun, sabar, dapat diandalkan | I6: 2 | J6: 牛 Kerbau 🐃 | K6: 蛇 Ular🐍, 雞 Ayam 🐓 | L6: 豬 Babi 🐷, 鼠 Tikus 🐭 | M6: 羊 Kambing 🐐 | N6: 鼠 Tikus 🐭
A7: 3 | B7: 08/02/1902 | C7: 28/01/1903 | D7: 虎 Macan 🐯 | E7: Air | F7: Yang | G7: Berani, kompetitif, tidak terduga | I7: 3 | J7: 虎 Macan 🐯 | K7: 馬 Kuda 🐴, 狗 Anjing 🐕 | L7: 兔 Kelinci 🐰, 龍 Naga 🐲 | M7: 猴 Monyet 🐒, 蛇 Ular🐍, 豬 Babi 🐷 | N7: 豬 Babi 🐷
A8: 4 | B8: 29/01/1903 | C8: 15/02/1904 | D8: 兔 Kelinci 🐰 | E8: Air | F8: Yin | G8: Lembut, elegan, waspada | I8: 4 | J8: 兔 Kelinci 🐰 | K8: 羊 Kambing 🐐, 豬 Babi 🐷 | L8: 龍 Naga 🐲, 虎 Macan 🐯 | M8: 雞 Ayam 🐓 | N8: 狗 Anjing 🐕
A9: 5 | B9: 16/02/1904 | C9: 03/02/1905 | D9: 龍 Naga 🐲 | E9: Kayu | F9: Yang | G9: Kuat, beruntung, karismatik | I9: 5 | J9: 龍 Naga 🐲 | K9: 鼠 Tikus 🐭, 猴 Monyet 🐒 | L9: 虎 Macan 🐯, 兔 Kelinci 🐰 | M9: 狗 Anjing 🐕 | N9: 雞 Ayam 🐓
A10: 6 | B10: 04/02/1905 | C10: 24/01/1906 | D10: 蛇 Ular🐍 | E10: Kayu | F10: Yin | G10: Bijaksana, misterius, intuitif | I10: 6 | J10: 蛇 Ular🐍 | K10: 牛 Kerbau 🐃, 雞 Ayam 🐓 | L10: 馬 Kuda , 羊 Kambing 🐐 | M10: 虎 Macan 🐯 | N10: 猴 Monyet 🐒
A11: 7 | B11: 25/01/1906 | C11: 12/02/1907 | D11: 馬 Kuda 🐴 | E11: Api | F11: Yang | G11: Energik, bebas, antusias | I11: 7 | J11: 馬 Kuda 🐴 | K11: 虎 Macan 🐯, 狗 Anjing 🐕 | L11: 羊 Kambing 🐐, 蛇 Ular🐍 | M11: 鼠 Tikus 🐭 | N11: 羊 Kambing 🐐
A12: 8 | B12: 13/02/1907 | C12: 01/02/1908 | D12: 羊 Kambing 🐐 | E12: Api | F12: Yin | G12: Seni, dermawan, pemalu | I12: 8 | J12: 羊 Kambing 🐐 | K12: 兔 Kelinci 🐰, 豬 Babi 🐷 | L12: 蛇 Ular🐍, 馬 Kuda 🐴 | M12: 牛 Kerbau 🐃 | N12: 馬 Kuda 🐴
A13: 9 | B13: 02/02/1908 | C13: 21/01/1909 | D13: 猴 Monyet 🐒 | E13: Tanah | F13: Yang | G13: Cerdik, serbabisa, kreatif | I13: 9 | J13: 猴 Monyet 🐒 | K13: 鼠 Tikus 🐭, 龍 Naga 🐲 | L13: 雞 Ayam 🐓, 狗 Anjing 🐕 | M13: 虎 Macan 🐯, 豬 Babi 🐷 | N13: 蛇 Ular🐍
A14: 10 | B14: 22/01/1909 | C14: 09/02/1910 | D14: 雞 Ayam 🐓 | E14: Tanah | F14: Yin | G14: Pekerja keras, jujur, teliti | I14: 10 | J14: 雞 Ayam 🐓 | K14: 牛 Kerbau 🐃, 蛇 Ular🐍 | L14: 狗 Anjing 🐕, 猴 Monyet 🐒 | M14: 兔 Kelinci 🐰 | N14: 龍 Naga 🐲
A15: 11 | B15: 10/02/1910 | C15: 29/01/1911 | D15: 狗 Anjing 🐕 | E15: Logam | F15: Yang | G15: Setia, jujur, keras kepala | I15: 11 | J15: 狗 Anjing 🐕 | K15: 虎 Macan 🐯, 馬 Kuda 🐴 | L15: 猴 Monyet 🐒, 雞 Ayam 🐓 | M15: 龍 Naga 🐲 | N15: 兔 Kelinci 🐰
A16: 12 | B16: 30/01/1911 | C16: 17/02/1912 | D16: 豬 Babi 🐷 | E16: Logam | F16: Yin | G16: Baik hati, murah hati, optimis | I16: 12 | J16: 豬 Babi 🐷 | K16: 羊 Kambing 🐐, 兔 Kelinci 🐰 | L16: 鼠 Tikus 🐭, 牛 Kerbau 🐃 | M16: 虎 Macan 🐯 | N16: 虎 Macan 🐯
A17: 13 | B17: 18/02/1912 | C17: 05/02/1913 | D17: 鼠 Tikus 🐭 | E17: Air | F17: Yang | G17: Cerdas, adaptif, oportunis
A18: 14 | B18: 06/02/1913 | C18: 25/01/1914 | D18: 牛 Kerbau 🐃 | E18: Air | F18: Yin | G18: Tekun, sabar, dapat diandalkan
A19: 15 | B19: 26/01/1914 | C19: 13/02/1915 | D19: 虎 Macan 🐯 | E19: Kayu | F19: Yang | G19: Berani, kompetitif, tidak terduga
A20: 16 | B20: 14/02/1915 | C20: 02/02/1916 | D20: 兔 Kelinci 🐰 | E20: Kayu | F20: Yin | G20: Lembut, elegan, waspada
A21: 17 | B21: 03/02/1916 | C21: 22/01/1917 | D21: 龍 Naga 🐲 | E21: Api | F21: Yang | G21: Kuat, beruntung, karismatik
A22: 18 | B22: 23/01/1917 | C22: 10/02/1918 | D22: 蛇 Ular🐍 | E22: Api | F22: Yin | G22: Bijaksana, misterius, intuitif
A23: 19 | B23: 11/02/1918 | C23: 31/01/1919 | D23: 馬 Kuda 🐴 | E23: Tanah | F23: Yang | G23: Energik, bebas, antusias
A24: 20 | B24: 01/02/1919 | C24: 19/02/1920 | D24: 羊 Kambing 🐐 | E24: Tanah | F24: Yin | G24: Seni, dermawan, pemalu
A25: 21 | B25: 20/02/1920 | C25: 07/02/1921 | D25: 猴 Monyet 🐒 | E25: Logam | F25: Yang | G25: Cerdik, serbabisa, kreatif
A26: 22 | B26: 08/02/1921 | C26: 27/01/1922 | D26: 雞 Ayam 🐓 | E26: Logam | F26: Yin | G26: Pekerja keras, jujur, teliti
A27: 23 | B27: 28/01/1922 | C27: 15/02/1923 | D27: 狗 Anjing 🐕 | E27: Air | F27: Yang | G27: Setia, jujur, keras kepala
A28: 24 | B28: 16/02/1923 | C28: 04/02/1924 | D28: 豬 Babi 🐷 | E28: Air | F28: Yin | G28: Baik hati, murah hati, optimis
... A123: 119 | B123: 16/02/2018 | C123: 04/02/2019 | D123: 狗 Anjing 🐕 | E123: Tanah | F123: Yang | G123: Setia, jujur, keras kepala
A124: 120 | B124: 43501 | C124: 24/01/2020 | D124: 豬 Babi 🐷 | E124: Tanah | F124: Yin | G124: Baik hati, murah hati, optimis
A125: 121 | B125: 25/01/2020 | C125: 11/02/2021 | D125: 鼠 Tikus 🐭 | E125: Logam | F125: Yang | G125: Cerdas, adaptif, oportunis
A126: 122 | B126: 12/02/2021 | C126: 31/01/2022 | D126: 牛 Kerbau 🐃 | E126: Logam | F126: Yin | G126: Tekun, sabar, dapat diandalkan
A127: 123 | B127: 01/02/2022 | C127: 21/01/2023 | D127: 虎 Macan 🐯 | E127: Air | F127: Yang | G127: Berani, kompetitif, tidak terduga
A128: 124 | B128: 22/01/2023 | C128: 09/02/2024 | D128: 兔 Kelinci 🐰 | E128: Air | F128: Yin | G128: Lembut, elegan, waspada
A129: 125 | B129: 10/02/2024 | C129: 28/01/2025 | D129: 龍 Naga 🐲 | E129: Kayu | F129: Yang | G129: Kuat, beruntung, karismatik
A130: 126 | B130: 29/01/2025 | C130: 16/02/2026 | D130: 蛇 Ular🐍 | E130: Kayu | F130: Yin | G130: Bijaksana, misterius, intuitif
A131: 127 | B131: 17/02/2026 | C131: 05/02/2027 | D131: 馬 Kuda 🐴 | E131: Api | F131: Yang | G131: Energik, bebas, antusias
A132: 128 | B132: 06/02/2027 | C132: 25/01/2028 | D132: 羊 Kambing 🐐 | E132: Api | F132: Yin | G132: Seni, dermawan, pemalu
A133: 129 | B133: 26/01/2028 | C133: 12/02/2029 | D133: 猴 Monyet 🐒 | E133: Tanah | F133: Yang | G133: Cerdik, serbabisa, kreatif
A134: 130 | B134: 13/02/2029 | C134: 02/02/2030 | D134: 雞 Ayam 🐓 | E134: Tanah | F134: Yin | G134: Pekerja keras, jujur, teliti
...

Sheet ELEMEN
A1: No | B1: Elemen | C1: SIFAT KARAKTER UTAMA
B2: ENERGY | C2: TINGGI | G2: NEGATIF | J2: WARNA SESUAI ELEMEN | K2: WARNA PENDUKUNG ELEMEN | L2: WARNA MELEMAHKAN ELEMEN LAIN | M2: SIKLUS TAHUN KEBRUNTUNGAN
A3: 1 | B3: LOGAM | C3: TERLAHIR SEBAGAI SEORANG PEMIMPIN SECARA ALAMI | D3: HEBAT DALAM MANAGEMEN(TERMASUK DIRI SENDIRI) | E3: KREATIF & INOVATIF | F3: PERCAYA DIRI | G3: EGOIS & KURANG EMPATI | H3: KURANG TRANSPARAN & | I3: AROGAN & EMOSIONAL | J3: PUTIH, EMAS, APRKOT,PERAK | K3: KUNING, KOPI, COKLAT TUA/MUDA | L3: HIJAU, CYAN | M3: MEMULAI SESUATU (BISNIS ATAU HAL BAIK APAPUN) | N3: PENUH TANTANGAN | O3: KEBERUNTUNGAN TINGGI
A4: 2 | B4: AIR | C4: TERLAHIR SEBAGAI SEORANG YANG AHLI BICARA / KOMUNIKASI | D4: MENGGUNAKAN BICARA UNTUK MENGHASILKAN APAPUN | E4: MUDAH BERADAPTASI GAYA KOMUNIKASI , RAMAH | F4: PENDENGAR YANG BAIK | G4: MUDAH RAGU RAGU | H4: MUDAH TERPENGARUH KEADAAN | I4: GOSSIP | J4: HITAM, BIRU, ABU ABU | K4: PUTIH, EMAS, APRKOT,PERAK | L4: MERAH, MERAH JAMBU, UNGU, ORANGE | M4: KERJASAMA & MENJAGA KESEIMBANGAN | N4: EVALUASI DARI TAHUN PERTAMA | O4: KEBERUNTUNGAN SEDANG
A5: 3 | B5: API | C5: TERLAHIR SEBAGAI SEORANG SUKA BERTINDAK | D5: PEMIKIR YANG KRITIS & PERCAYA DIRI | E5: CEPAT MENANGKAP PELUANG / MATA TAJAM | F5: PANTANG MENYERAH & MANDIRI | G5: IMPLUSIF | H5: KURANG MENIMBANG PERASAAN ORANG LAIN | I5: DOMINAN, KURANG SABAR | J5: MERAH, MERAH JAMBU, UNGU, ORANGE | K5: HIJAU, CYAN | L5: PUTIH, EMAS, APRKOT,PERAK | M5: TINDAKAN YANG KONSISTEN | N5: KOMITMEN & PANTANG MENYERAH | O5: KEBERUNTUNGAN RENDAH
A6: 4 | B6: KAYU | C6: TERLAHIR SEBAGAI SEORANG YANG SUKA MEMBUAT RENCANA | D6: TELITI & DETAIL (SELALU MENCARI JAWABAN) | E6: TERORGANISIR & DISIPLIN & PINTAR MERANGKUM (KESIMPULAN) | F6: ORIENTASI TUJUAN & DAPAT DIANDALKAN | G6: TELALU BANYAK PIKIRAN (LAMBAT MENGAMBIL KEPUTUSAN) | H6: KAKU/TIDAK FLEKSIBEL | I6: CEPAT KUATIR & MUDAH KECEWA | J6: HIJAU, CYAN | K6: HITAM, BIRU, ABU ABU | L6: KUNING, KOPI, COKLAT TUA/MUDA | M6: PERENCANAAN TUJUAN, SUMBER DAYA & RESIKO | N6: STABILITAS (BUTUH AMAL BAKTI) | O6: KEBERUNTUNGAN SEDANG
A7: 5 | B7: TANAH | C7: TERLAHIR SEBAGAI SEORANG PEMIMPIN DIATAS PARA PEMIMPIN | D7: PUNYA TUJUAN&ARAH JELAS (AHLI NAVIGASI) | E7: MUDAH MENYATUKAN ORANG | F7: TEGAS,STARTEGIS & BERINTERGRITAS | G7: OTORITER, SOMBONG | H7: SULIT MENERIMA KRITIK & MENDENGAR | I7: KURANG SABAR | J7: KUNING, KOPI, COKLAT TUA/MUDA | K7: MERAH, MERAH JAMBU, UNGU, ORANGE | L7: HITAM, BIRU, ABU ABU | M7: MENENTUKAN ARAH & KETEGUHAN | N7: TRANSISI | O7: KEBERUNTUNGAN TINGGI
A8: 6 | B8: LOGAM | C8: TERLAHIR SEBAGAI SEORANG YANG MEMILIKI INDERA KE-6 MENGENAI UANG | D8: MAGNET UANG | E8: KREATIF DALAM MENCARI PELUANG | F8: PEKA & PANDAI MENGELOLA UANG | G8: TERLALU MATERIALISTIS & BOROS | H8: PEMILIH DALAM BERGAUL | I8: TERLALU BERHITUNG & SERAKAH | J8: PUTIH, EMAS, APRKOT,PERAK | K8: KUNING, KOPI, COKLAT TUA/MUDA | L8: HIJAU, CYAN | M8: MEMANEN UANG (BAGI HASIL) | N8: KEBIJAKSANAAN (MENGERTI MEMBERI & MENERIMA) | O8: KEBERUNTUNGAN TERMASUK TINGGI
A9: 7 | B9: AIR | C9: TERLAHIR SEBAGAI SEORANG YANG PALING BERUNTUNG (HAPPY GO LUCKY) | D9: BANYAK PENDUKUNG & BERJIWA SOSIAL | E9: BANYAK PELUANG & KONEKSI & KETRAMPILAN OBSERVASI YANG KUAT | F9: MUDAH BERGAUL & OPTIMIS | G9: MUDAH TERPENGARUH OPINI | H9: SUKA CARI PERHATIAN | I9: SOMBONG | J9: HITAM, BIRU, ABU ABU | K9: PUTIH, EMAS, APRKOT,PERAK | L9: MERAH, MERAH JAMBU, UNGU, ORANGE | M9: MEMBANGUN RELASI | N9: PENUH KEJUTAN | O9: KEBERUNTUNGAN TINGGI
A10: 8 | B10: API | C10: TERLAHIR SEBAGAI SEORANG YG MEMPUNYAI SIFAT TANGGUNG JAWAB | D10: MENGUTAMAKAN ORANG LAIN (PERHATIAN) | E10: MEMPUNYAI ETOS KERJA | F10: JUJUR & BERINTEGRITAS & DERMAWAN | G10: KURANG BERPIKIR KE DIRI SENDIRI | H10: STRESS&KURANG WAKTU SENDIRI | I10: PERFEKSIONIS(SUSAH MENDELEGASI) | J10: MERAH, MERAH JAMBU, UNGU, ORANGE | K10: HIJAU, CYAN | L10: PUTIH, EMAS, APRKOT,PERAK | M10: MEMBANGUN KEKUASAAN | N10: MEMBANGUN TANGGUNG JAWAB | O10: KEBERUNTUNGAN RENDAH
A11: 9 | B11: KAYU | C11: TERLAHIR SEBAGAI SEORANG YANG VISIONER(IMAJINATIF) | D11: KUAT DALAM PIKIRAN & KEYAKINAN (APA YANG DIPIKIRKAN AKAN MUDAH DIDAPATKAN) | E11: KHARISMATIK & OPTIMIS (MENTAL KUAT) | F11: INTUITIF, MUDAH & CEPAT MENARIK PELUANG | G11: TIDAK KONSISTEN, EKSPETASI TERLALU TINGGI | H11: MUDAH STRESS & TERSUGESTI | I11: SULIT MENGONTROL EMOSI & PIKIRAN | J11: HIJAU, CYAN | K11: HITAM, BIRU, ABU ABU | L11: KUNING, KOPI, COKLAT TUA/MUDA | M11: MENIKMATI HASIL (PENUTUP) | N11: PERSIAPAN SIKLUS BARU YANG LEBIH BAIK | O11: KEBERUNTUNGAN TERMASUK TINGGI
B13: 5 Berkat Kehidupan
A14: No
A15: 4 | C15: Mendapatkan Berkat KEBAHAGIAN ( Lahan / Tanah / Perumahan / Aset )
A16: 5 | C16: Mendapatkan Berkat KEDUDUKAN ( Posisi, Karir )
A17: 6 | C17: Mendapatkan Berkat KEBERUNTUNGAN/KEBIJAKSANAAN (Makan / Kekayaan)
A18: 7 | C18: Mendapatkan Berkat KEPOPULERAN ( Kekuasaan / Orang Pendukung )
A19: 9 | C19: Mendapatkan Berkat PANJANG UMUR/KESUKSESAN ( Kesejateraan Hidup - XI YUE HONG )
B21: IMPIAN HIDUP (BAWAAN LAHIR) | D21: Dalam Segitiga Butuh
A22: 1 | C22: MENJADI PEMIMPIN (LEADER, DIREKTUR, MANAGER) | D22: 1 (Leader), 5 (Arah), 7 (Orang Pendukung) | E22: 9 (Hasil)
A23: 2 | C23: MENJADI PEMBICARA HANDAL (MOTIVATOR, PENCERAMAH) | D23: 2 (Komunikasi), 7 (Orang Pendukung), 9 (Hasil)
A24: 3 | C24: MENJADI BANGSAWAN | D24: 3 (Tindakan), 6 (Uang)
A25: 4 | C25: MENJADI PLANNER (KONSELOR, KONSULTAN) | D25: 2 (Komunikasi), 4 (Rencana), 9 (Hasil)
A26: 5 | C26: MENJADI KETUA PARA PEMIMPIN (CEO, RAJA, KETUA UMUM) | D26: 1 (Leader), 4 (Rencana), 5 (Arah), | E26: 7 (Orang Pendukung), 8 (Bertanggung Jawab), 9 (Hasil)
A27: 6 | C27: MENJADI PENGUSAHA, INVESTOR, BANKIR, OLIGARKI | D27: 3 (Tindakan), 6 (Uang)
A28: 7 | C28: MENJADI PENGENDALI SEMUA ORANG | D28: 2 (Komunikasi), 7 (Orang Pendukung), 9 (Hasil)
A29: 8 | C29: MENDAPATKAN HAK ANDA SENDIRI (KUASA) | D29: 2 (Komunikasi), 4 (Rencana), 5 (Arah) | E29: 8 (Bertanggung Jawab), 9 (Hasil)
A30: 9 | C30: MENGUASAI DUNIA | D30: 1 (Leader), 2 (Komunikasi), 4 (Rencana) | E30: 5 (Arah), 7 (Orang Pendukung), 9 (Hasil)

Sheet 81SET
C2: Gabungan Angka Benturan API dan AIR | D2: 123, 213, 178, 718, 235, 325, 268, 628, 281, 821, 347, 437, 371, 731, 382, 832, 573, 753, 786, 876, 887
C3: Potensi Menyebabkan Gagal Bisnis/Karir | D3: 112, 123, 213, 393, 933, 167, 358, 538
C4: Potensi Menyebabkan Masalah Keharmonisan Keluarga | D4: 112, 123, 213, 167, 191, 911, 134, 314, 145, 279, 729, 415, 382, 832, 483, 843, 786, 876, 887, 999
C5: Potensi Bermasalah di Kesehatan | D5: 112, 189, 819, 382, 832, 393, 933, 494, 944, 898, 988
C6: Potensi Terkena Masalah Hukum | D6: 112, 178, 718, 224, 292, 922, 731, 483, 843, 448, 595, 955, 999
C7: Potensi Memiliki Kekayaan Yang Besar | D7: 156, 516, 336, 663, 369, 639, 696, 966, 999
B10: MAKNA DARI GABUNGAN 81 SET
B11: Set | C11: Makna / Penjelasan
B12: 112 | C12: Orang Yang Sangat Percaya Diri & Pintar Bicara, 1 org dengan 1 org = komunikasi sangat keras, ada kuasa, status pernikahan yang berbeda/pasti tidak bahagia/ kalaupun pernikakan bahagia, tp tetap satu di sini dan satu di sana, status kesehatan yang kurang dan di atas usia 40 tahun tidak di senangin lagi di ajak bicara oleh orang lain. dan sanagat keras pendirian.
B13: 123 | C13: Pintar Bicara, Jikalau buat presetasi sangat terstruktur, (-) omongan bisa sangat bagus tetapi orang lain tidak ngerti, bisa nyinggung orang/ sakrkastik, jadi energy harus tinggi
B14: 213 | C14: Harus Bicara Yang Benar/Jujur, omongan benar, tapi orang lain tidak suka dengarnya, harus ngomong yang bagus, berpikir dengan baik dan omongan jadi baik, bisa jadi jendral dan tidak boleh bilang yang tidak baik
B15: 134 | C15: Orang yang sangat baik hati (suka menolong), Rajin, Perlu Banyak Belajar Bersabar, Harus Buat Banyak Amal Bakti Baru Bisa Mempunyai Peruntungan, buat usaha apapun sangat stabil. (-) punya rasa dendam/ pendendam, suka ingat yang tidak baik dan yang baik tidak mau di ingat. bisa jadi usahawan / ilmuwan
B16: 314 | C16: harus selalu berpikiran positif, kalau energy kuat, buat apapun bahagia, kalau enerli rendah bisa di bawa sampai kerumah, harus bisa kontrol emosi, saat bahagia bisa sangat bahagia dan sebaliknya
B17: 145 | C17: Perlu Meningkatkan Keahlian Untuk Berkembang, Suka Berencana, Jikalaupun berencana mesti bisa buat setting goal yang lebih tinggi (-) keputusan tidak sesuai dengan perencanaan, planning kebanyakan tidak jadi kalau tidak ada angka penolong, sebelum nikah ada perpect dream, begitu nikah beda lagi.
B18: 415 | C18: Berpikir adalah masalah, Berbuat adalah jawaban. Bisa berhasil dan bisa tidak berhasil. Jangan berpikir, berbuat aja. Energy harus tinggi, banyak rintangan kalau tidak ada angka 9
B19: 156 | C19: Perlu Keluar kota untuk mendapatkan hasil yang baik, keluar dari kota kelahiran, kalau ada pressure/ tekanan keluar sebentar.
B20: 516 | C20: Personal Dirinya Mesti Keluar Dari Kota Kelahiran Untuk Mencari Penghasilan Jikalau Mau Dapat Hasil Yang Besar, yang penting keluar jalan jalan, karena ada arah, yakin buat apa bis dapat apa (-) punya hobby yang tidak sehat ( minum, judi dll yang habiskan uang)
B21: 167 | C21: Orang Yang Berbakat Bisnis. Pinter cari tempat makan yang sedap, punya simpanan khusus. Satu org cari uang, semua orang bisa menikmati uangnya, ada hoki, mau usaha apapun tapi usaha sendiri kalau di kasi modal tidak aman membuat sukses.
B22: 617 | C22: Jangan menikah sebelum 30 taon, kalau bisnis jangan ambil uang orang tua hidup macam rolly coster (cendrung Boros), selalu maman makanan yang enak, suka traktir orang makan, selsalu berusaha sendiri baru sukses, jgn berpuas diri, akan terus bekerja terus, harus ada simpanan/uang/ jgn di habiskan, terhadap uang sangat sensitif, lebih jaga diri sendiri duluan.
B23: 178 | C23: Gak Boleh Pinjam Orang Uang/Kendaraan tapi boleh kasih , Gak Boleh Garansi Orang. Jikalau mau peruntungan bagus mesti buat perjalanan ke luar kota minimal 4 jam melalui udara (-) selalu kena masalah hukum, suka di gisipin / di fitnah, masalah kecil yang bisa di jadikan masalah besar, bisa dapat uang global dan tidak boleh jadi pemimpin no. 1
... B92: 999 | C92: Terlalu Banyak Peluang, Energy Mesti Tinggi Sekali, Bisa Jadi Raja Atau Tahanan, Bisa Sukses Besar Atau Gagal Total, Rumah Tangga Bisa Sangat harmonis Atau Tinggal Diri Sendiri, tuaho tuaphai. Energy tinggi bisa jadi sukses besar, energy rendah bisa jadi pengemis atau tekena masalah hukum. bila di main karakter, beli barang harus yang high quality, jiak di set 6, anak sulung opposit dengan kita, jika di set 9, tidak ada teman sejati, tinggal sendiri saja.
B98: MAKNA DARI GABUNGAN 81 SET ANGKA DI STRUKTUR 13 SET ANGKA DI SEGITIGA DIRI SENDIRI
C100: 1 | D100: 2 | E100: 3 | F100: 4 | G100: 5 | H100: 6 | I100: 7 | J100: 8 | K100: 9 | L100: 10 | M100: 11 | N100: 12 | O100: 13
C101: DNA AYAH | D101: DNA IBU | E101: KARAKTER UTAMA | F101: P. Perjalanan(1) | G101: P. Perjalanan(2) | H101: Anak | I101: Karir(1) | J101: Karir(2) | K101: Teman | L101: Pernikahan(1) | M101: Pernikahan(2) | N101: Masa Depan | O101: Alam Bawah Sadar
B102: 112
B103: 123
B104: 134
B105: 145
B106: 156
B107: 167
B108: 178
B109: 189
B110: 191
B111: 213
B112: 224
B113: 235
... B182: 999
